Workbook

Sheet README
A1: Cat home financial model (Checkpoint 4, Phase G)
A2: Investor-style e-commerce study | as of October 19, 2026 | US Shopify DTC
A4: PURPOSE
A5: Unit economics, 24-month cohort LTV, scenarios, sensitivities, launch cash and go/no-go gates for:
A6: BASE CASE: cat home brand - corded/USB stainless water fountain with a 90-day filter pack subscription (US-stocked filters), litter mat add-on.
A7: SHADOW CASE: espresso upgrade brand - De'Longhi Dedica / 51mm kit (portafilter, tamper, WDT, puck screen) with beans via Roastify / Dripshipper.
A9: IMPORTANT: inputs tagged ASSUMPTION are the analyst's planning values. They are NOT market facts and must be replaced with quotes, test results and real campaign data as they arrive. Only FILING / VENDOR / SECONDHAND rows trace to a cited source; ESTIMATE rows are arithmetic on cited inputs.
A11: SCENARIO SELECTOR
A12: Change Inputs!D3 (1 = Pessimistic, 2 = Base, 3 = Optimistic). Current selection: | B12: =Inputs!$D$3 -> 2 | C12: =Inputs!$E$3 -> Base
A13: Change Inputs!D4 (1 = Test stage: AliExpress + CPA m1-3; 2 = Private label + CPA m4-12) to choose which first order the cohort uses: | B13: =Inputs!$D$4 -> 2 | C13: =Inputs!$E$4 -> Private label (OEM + 3PL, CPA months 4-12)
A14: Change Inputs!D5 (1 = Lean, 2 = Moderate, 3 = Higher-capital) to choose the launch tier used by GoNoGo: | B14: =Inputs!$D$5 -> 1 | C14: =Inputs!$E$5 -> Lean
A15: The Scenarios sheet always shows all three scenarios side by side (independent engine columns), whatever the selector says.
A17: HOW TO USE
A18: 1. Edit only blue cells on light-yellow fill (Inputs sheet; shock sizes and two-way axes on Sensitivity). Everything else is a formula.
A19: 2. Read results: Cat_UnitEcon / Espresso_UnitEcon (per order), Cat_Cohort / Espresso_Cohort (24-month cohort, top block = selected scenario).
A20: 3. Compare: Scenarios (P/B/O both cases), Sensitivity (base-case shocks + CPA x attach tables), Launch_Budget (cash), GoNoGo (gates).
A21: 4. Engine columns/blocks to the right of / below the selected views feed Scenarios and Sensitivity. Do not edit them.
A23: COLOR LEGEND
A24: Input (hardcoded, editable) | B24: 123.45
A25: Selector / key control | B25: 2
A26: Formula (calculation) | B26: =B24*2 -> 246.9
A27: Formula that links to another sheet | B27: =Inputs!$D$3 -> 2
A28: Key output | B28: =B24 -> 123.45
A30: SHEETS
A31: Inputs - every driver with Pessimistic / Base / Optimistic, Selected (CHOOSE on D3), source tag and URL/note; USPS rate card; launch tiers; gate thresholds.
A32: Cat_UnitEcon - (a) fountain first order at test stage, (b) at private label, (c) fountain + mat bundle, (d) filter renewal, (e) one-time filter order; contribution before ads, after CPA, break-even CPA.
A33: Cat_Cohort - 100 customers, 3 segments (one-time, occasional repeat, subscribers), monthly contribution, cumulative after CAC, payback, 12/24-month contribution LTV.
A34: Espresso_UnitEcon / Espresso_Cohort - same structure for the shadow case (monthly bean subscription).
A35: Scenarios - P/B/O outputs for both cases. Sensitivity - CPA +30%, COGS +15%, shipping +20%, attach -50%, churn +50%, returns 2x; two-way tables.
A36: Launch_Budget - lean / moderate / higher-capital one-time costs, monthly fixed costs, test ads, cash before first PL sale, runway, break-even volume.
A37: GoNoGo - model-derived CPA ceilings, margin, payback, LTV:CAC, renewal economics, minimum attach and cash gates with GO / CONDITIONAL / NO-GO.
A38: Repositioned - base-cost tests of repositioned offers (R1 $79 easy-clean system; R2 = R1 + 6-month 12-filter subscription; R3 = R2 + affiliate/organic CPA cut; R4 = R2 + non-China OEM; R6 = all cat levers; R5 = espresso kit at $99), each with its own cohort, launch cash and gate results.
A40: CONVENTIONS
A41: LTV = contribution profit (net revenue less all variable costs), never revenue. First-order profitability is reported separately everywhere.
A42: Month 1 = acquisition month. Filter renewals bill every 3 months from month 4 (90-day pack). Bean renewals bill monthly from month 2.
... A60: Inputs research: research_notes/Cat home financial model/cost_inputs.md and acquisition_retention.md; reports/Espresso and cat validation.md (CP3); reports/Category brand subscription deep dive.md (CP2). Client defaults: CP3 Section 9.

Sheet Inputs
A1: Inputs: every driver, Pessimistic / Base / Optimistic, with Selected column
A2: Blue cells on light-yellow fill are inputs. Black cells are formulas. Rows tagged ASSUMPTION are the analyst's planning values, NOT market facts. As of Oct 19, 2026 (Checkpoint 4).
B3: Scenario selector: 1 = Pessimistic, 2 = Base, 3 = Optimistic | D3: 2 | E3: =CHOOSE($D$3,"Pessimistic","Base","Optimistic") -> Base
B4: First-order / cohort stage: 1 = Test stage (AliExpress + CPA months 1-3); 2 = Private label (CPA months 4-12) | D4: 2 | E4: =CHOOSE($D$4,"Test stage (AliExpress dropship, CPA months 1-3)","Private label (OEM + 3PL, CPA months 4-12)") -> Private label (OEM + 3PL, CPA months 4-12)
B5: Launch budget tier: 1 = Lean, 2 = Moderate, 3 = Higher-capital | D5: 1 | E5: =CHOOSE($D$5,"Lean","Moderate","Higher-capital") -> Lean
A7: ID | B7: Driver | C7: Unit | D7: Pessimistic | E7: Base | F7: Optimistic | G7: Selected | H7: Source tag | I7: Source URL / note
B8: Model controls
A9: cohort_size | B9: Cohort size (customers acquired) | C9: customers | D9: 100 | E9: 100 | F9: 100 | G9: =CHOOSE($D$3,D9,E9,F9) -> 100 | H9: ASSUMPTION | I9: Structural: 100-customer cohort per Checkpoint 4 spec.
B10: A. Retail prices (customer-facing, free shipping unless stated)
A11: p_fountain | B11: Cat fountain (corded/USB stainless) retail price | C11: $/unit | D11: 44.99 | E11: 49.99 | F11: 59.99 | G11: =CHOOSE($D$3,D11,E11,F11) -> 49.99 | H11: ASSUMPTION | I11: Feature tier $35-$65: Petlibro Dockstream $60.89-$62.99, Capsule $36.99 (Cats.com, Sep 18 2026, https://cats.com/best-cat-water-fountain). CP3 landed-cost table used $49.99. Amazon generics $18.99-$19.99 (CP3 Sec.2).
A12: p_filter_onetime | B12: Filter 90-day pack (6 filters), one-time price | C12: $/pack | D12: 14.99 | E12: 16.99 | F12: 17.49 | G12: =CHOOSE($D$3,D12,E12,F12) -> 16.99 | H12: ASSUMPTION | I12: CONFLICT: CP2 suggested ~$19.99/quarter; CP3 says price under Petlibro ~$2.62/filter subscribed = $15.72 per 6 (https://petlibro.com/products/dockstream-2-smart-fountain-replacement-filter). Conservative: subscription price kept under the CP3 anchor.
A13: sub_disc | B13: Subscription discount on filter pack | C13: % | D13: 0.15 | E13: 0.1 | F13: 0.1 | G13: =CHOOSE($D$3,D13,E13,F13) -> 0.1 | H13: ASSUMPTION | I13: Petlibro 30% first order then 10%; Chewy 35% first Autoship (CP2/CP3).
A14: p_filter_sub | B14: Filter pack subscription price (formula) | C14: $/pack | D14: =D12*(1-D13) -> 12.7415 | E14: =E12*(1-E13) -> 15.291 | F14: =F12*(1-F13) -> 15.741 | G14: =CHOOSE($D$3,D14,E14,F14) -> 15.291 | H14: ESTIMATE | I14: One-time price x (1 - discount). Base $15.29 = $2.55/filter, under the $2.62 Petlibro anchor.
A15: filters_per_pack | B15: Filters per 90-day pack | C15: filters | D15: 6 | E15: 6 | F15: 6 | G15: =CHOOSE($D$3,D15,E15,F15) -> 6 | H15: ASSUMPTION | I15: Client-approved default: 90-day 6-pack cadence (CP3 Sec.9 #5).
A16: ship_charge_filter | B16: Shipping charged on one-time (non-subscription) filter orders | C16: $/order | D16: 0 | E16: 0 | F16: 3.99 | G16: =CHOOSE($D$3,D16,E16,F16) -> 0 | H16: ASSUMPTION | I16: Base keeps free shipping to compete with Prime generic filters (32 for $16.99, CP3 Sec.5).
A17: p_mat | B17: Litter mat add-on price | C17: $/unit | D17: 16.99 | E17: 19.99 | F17: 22.99 | G17: =CHOOSE($D$3,D17,E17,F17) -> 19.99 | H17: ASSUMPTION | I17: Amazon Cat Litter Mats best sellers $8-$23 (CP3 Sec.2, https://www.amazon.com/Best-Sellers-Pet-Supplies-Cat-Litter-Mats/zgbs/pet-supplies/17295526011).
A18: p_kit | B18: Espresso Dedica 51mm upgrade kit price (portafilter + tamper + WDT + puck screen) | C18: $/kit | D18: 74.99 | E18: 84.99 | F18: 99.99 | G18: =CHOOSE($D$3,D18,E18,F18) -> 84.99 | H18: ASSUMPTION | I18: Espresso first-order AOV assumption $70/$85/$105 (acquisition_retention.md Q2). Dedica Essential stack $90-$120 (https://completehomebarista.com/guides/best-upgrades-delonghi-dedica-ec685). Amazon 7-pc Breville kit $42.98-$45.99 anchor.
A19: kit_pieces | B19: Pieces (picks) per espresso kit | C19: items | D19: 4 | E19: 4 | F19: 4 | G19: =CHOOSE($D$3,D19,E19,F19) -> 4 | H19: ASSUMPTION | I19: Kit composition used in the model.
A20: p_beans_onetime | B20: Beans shipment (2 x 12oz), one-time price incl. shipping | C20: $/shipment | D20: 37.99 | E20: 39.99 | F20: 43.99 | G20: =CHOOSE($D$3,D20,E20,F20) -> 39.99 | H20: ASSUMPTION | I20: CP2 bean subscription anchor $34-$40 incl. shipping (Trade, Bean Box, Atlas).
A21: bean_sub_disc | B21: Bean subscription discount | C21: % | D21: 0.1 | E21: 0.1 | F21: 0.1 | G21: =CHOOSE($D$3,D21,E21,F21) -> 0.1 | H21: ASSUMPTION | I21: Mirrors filter discount.
A22: p_beans_sub | B22: Beans shipment subscription price (formula) | C22: $/shipment | D22: =D20*(1-D21) -> 34.191 | E22: =E20*(1-E21) -> 35.991 | F22: =F20*(1-F21) -> 39.591 | G22: =CHOOSE($D$3,D22,E22,F22) -> 35.991 | H22: ESTIMATE | I22: One-time x (1 - discount).
A23: bags_per_ship | B23: 12oz bags per bean shipment | C23: bags | D23: 2 | E23: 2 | F23: 2 | G23: =CHOOSE($D$3,D23,E23,F23) -> 2 | H23: ASSUMPTION | I23: CP2 offer: 2 x 12oz every 2-4 weeks; modeled monthly.
B24: B. COGS - test stage (AliExpress via AutoDS dropship; supplier ships free)
A25: ali_fountain | B25: AliExpress corded stainless fountain unit price | C25: $/unit | D25: 34.08 | E25: 28.39 | F25: 21.79 | G25: =CHOOSE($D$3,D25,E25,F25) -> 28.39 | H25: VENDOR | I25: CP3 Sec.3.2: ROJECO 2L 'US Adapter New' $28.39 (https://www.aliexpress.us/item/3256808061782685.html); search band $21.79-$42.81; listed $26.91-$34.08. Welcome prices may vanish.
A26: test_duty | B26: Duty / price pass-through on China parcels (test stage) | C26: % of item | D26: 0.375 | E26: 0.3 | F26: 0 | G26: =CHOOSE($D$3,D26,E26,F26) -> 0.3 | H26: ESTIMATE | I26: Unresolved whether AliExpress collects duty (CP3 Case A 0% vs Case B). cost_inputs.md Q4 planning: 25-40%, ~30%. Pess = full 37.5% stack.
A27: autods_fee | B27: AutoDS wallet / card fee on supplier cost | C27: % of item | D27: 0.05 | E27: 0.05 | F27: 0 | G27: =CHOOSE($D$3,D27,E27,F27) -> 0.05 | H27: SECONDHAND | I27: CONFLICT: CP3 cites AutoDS help (5% card, https://help.autods.com/en/articles/12700443-automate-your-orders-with-fulfilled-by-autods-fba); cost_inputs.md says not verified (base 0%). Conservative base = 5%.
A28: test_lost | B28: Duty-refused / lost / re-ship parcels (test stage) | C28: % of orders | D28: 0.07 | E28: 0.05 | F28: 0.02 | G28: =CHOOSE($D$3,D28,E28,F28) -> 0.05 | H28: ASSUMPTION | I28: cost_inputs.md Q4: budget ~5% risk of duty-due refusals or re-ships; returns to China uneconomic.
A29: ali_pf | B29: AliExpress 51mm Dedica bottomless portafilter | C29: $/unit | D29: 25.66 | E29: 17.53 | F29: 17.01 | G29: =CHOOSE($D$3,D29,E29,F29) -> 17.53 | H29: VENDOR | I29: Listing 3256809164814557: $17.01-$25.66 (https://www.aliexpress.us/item/3256809164814557.html).
A30: ali_tamper | B30: AliExpress 51mm tamper | C30: $/unit | D30: 14.09 | E30: 13.28 | F30: 12.37 | G30: =CHOOSE($D$3,D30,E30,F30) -> 13.28 | H30: VENDOR | I30: PERFFEE 51mm $13.28-$14.09 (https://www.aliexpress.us/item/3256806759653263.html); same 51mm listing $12.37-$13.99.
A31: ali_wdt | B31: AliExpress WDT tool | C31: $/unit | D31: 13.09 | E31: 6.33 | F31: 1.14 | G31: =CHOOSE($D$3,D31,E31,F31) -> 6.33 | H31: VENDOR | I31: $13.09 clicked SKU; $6.33 low of search band; $1.14 Bundle Deals welcome price (CP3 Sec.3.1).
A32: ali_screen | B32: AliExpress 51mm puck screen | C32: $/unit | D32: 11.14 | E32: 4.98 | F32: 1.29 | G32: =CHOOSE($D$3,D32,E32,F32) -> 4.98 | H32: VENDOR | I32: 51mm magnet $11.14; 2-pc $9.95 (=$4.98/pc); 51mm 1-pc welcome $1.29 (https://www.aliexpress.us/item/3256809211885821.html).
A33: ali_kit | B33: AliExpress Dedica kit component cost (formula) | C33: $/kit | D33: =D29+D30+D31+D32 -> 63.98 | E33: =E29+E30+E31+E32 -> 42.12 | F33: =F29+F30+F31+F32 -> 31.81 | G33: =CHOOSE($D$3,D33,E33,F33) -> 42.12 | H33: ESTIMATE | I33: Sum of components; arrives as several parcels (CP3).
A34: test_duty_esp | B34: Duty / pass-through on espresso parcels (test stage) | C34: % of item | D34: 0.414 | E34: 0.3 | F34: 0 | G34: =CHOOSE($D$3,D34,E34,F34) -> 0.3 | H34: ESTIMATE | I34: Pess = List 3 25% + 12.5% forced-labor 301 + ~3.9% MFN; base 30% planning pass-through; opt Case A.
B35: C. COGS - private-label stage, cat (OEM, sea LCL, 3PL)
A36: oem_fountain | B36: OEM corded stainless fountain FOB (500 MOQ) | C36: $/unit | D36: 10.83 | E36: 9.77 | F36: 6.66 | G36: =CHOOSE($D$3,D36,E36,F36) -> 9.77 | H36: VENDOR | I36: Petwant 2L $6.66-$7.33, 2.7L $9.77-$10.52 at 500 MOQ (https://www.alibaba.com/product-detail/Petwant-OEM-ODM-2-7L-Stainless_1601927624978.html); CP2 wholesale $10.00-$10.83. Search-card data; fresh quotes needed. Non-China quotes requested in parallel (client default).
A37: adapter_premium | B37: UL 1310 / ETL-listed adapter premium | C37: $/unit | D37: 3 | E37: 2 | F37: 1.5 | G37: =CHOOSE($D$3,D37,E37,F37) -> 2 | H37: ASSUMPTION | I37: cost_inputs.md Q5: +$1.50-$3.00 vs unlisted; only retail listed-adapter prices found ($6.55-$10.98).
A38: fountain_freight | B38: Ocean LCL freight + destination charges per fountain | C38: $/unit | D38: 5 | E38: 3.5 | F38: 2.2 | G38: =CHOOSE($D$3,D38,E38,F38) -> 3.5 | H38: ESTIMATE | I38: CONFLICT: CP3 $1.00-$2.50 (unsourced) vs cost_inputs.md Q3 $2.20-$4.60, base $3.50, $5.00 at 2026 peak. Conservative base $3.50.
A39: fountain_duty | B39: Fountain duty stack (HTS 8413.70.2004: MFN 0% + 301 List 1 25% + 301 forced-labor 12.5%) | C39: % of FOB | D39: 0.375 | E39: 0.375 | F39: 0.375 | G39: =CHOOSE($D$3,D39,E39,F39) -> 0.375 | H39: FILING | I39: CBP rulings N303286/N303288 (https://www.tarifflens.ai/rulings/N303286); 12.5% from Jul 24 2026 (https://www.chrobinson.com/en-us/resources/blog/section-301-forced-labor-tariffs/). Section 232 risk unverified (broker).
A40: moq_fountain | B40: Units per import entry (fountain MOQ) | C40: units | D40: 500 | E40: 500 | F40: 1000 | G40: =CHOOSE($D$3,D40,E40,F40) -> 500 | H40: ASSUMPTION | I40: Client default: commit 500-1,000 MOQ only after creative win + passed samples (CP3 Sec.9 #3).
A41: broker_fee | B41: Customs broker entry fee | C41: $/entry | D41: 250 | E41: 150 | F41: 100 | G41: =CHOOSE($D$3,D41,E41,F41) -> 150 | H41: VENDOR | I41: $100-$250 (Strix), $150-$350 (GingerControl) (https://strixsmart.com/resources/blog/customs-broker-cost).
...

Sheet Cat_UnitEcon
A1: Cat_UnitEcon: per-order contribution, cat home (BASE CASE)
A2: Group 1 (columns B-F) follows the scenario selector. Groups to the right are the engine for Scenarios and Sensitivity: identical formulas pointing at a fixed Inputs column, some with a shock multiplier.
A3: Costs shown as negatives. Contribution = net revenue less all variable costs (product, fulfillment, postage, payments, warranty, returns, chargebacks, affiliates). Fixed costs (apps, 3PL storage, UGC) are in Launch_Budget.
A5: Scenario group | B5: ="SELECTED scenario: "&Inputs!$E$3 -> SELECTED scenario: Base | H5: PESSIMISTIC (engine) | N5: BASE (engine) | T5: OPTIMISTIC (engine) | Z5: BASE + CPA shock (sensitivity) | AF5: BASE + supplier/COGS shock (sensitivity) | AL5: BASE + shipping shock (sensitivity) | AR5: BASE + subscription-attach shock (sensitivity) | AX5: BASE + churn shock (sensitivity) | BD5: BASE + returns shock (sensitivity)
A6: Inputs column used | B6: G = Selected | H6: D = Pessimistic | N6: E = Base | T6: F = Optimistic | Z6: E = Base | AF6: E = Base | AL6: E = Base | AR6: E = Base | AX6: E = Base | BD6: E = Base
A7: Multiplier - paid CPA | B7: 1 | H7: 1 | N7: 1 | T7: 1 | Z7: =1+Sensitivity!$C$5 -> 1.3 | AF7: 1 | AL7: 1 | AR7: 1 | AX7: 1 | BD7: 1
A8: Multiplier - supplier unit cost (COGS) | B8: 1 | H8: 1 | N8: 1 | T8: 1 | Z8: 1 | AF8: =1+Sensitivity!$C$6 -> 1.15 | AL8: 1 | AR8: 1 | AX8: 1 | BD8: 1
A9: Multiplier - postage | B9: 1 | H9: 1 | N9: 1 | T9: 1 | Z9: 1 | AF9: 1 | AL9: =1+Sensitivity!$C$7 -> 1.2 | AR9: 1 | AX9: 1 | BD9: 1
A10: Multiplier - subscription attach (used in cohort) | B10: 1 | H10: 1 | N10: 1 | T10: 1 | Z10: 1 | AF10: 1 | AL10: 1 | AR10: =1+Sensitivity!$C$8 -> 0.5 | AX10: 1 | BD10: 1
A11: Multiplier - churn (used in cohort) | B11: 1 | H11: 1 | N11: 1 | T11: 1 | Z11: 1 | AF11: 1 | AL11: 1 | AR11: 1 | AX11: =1+Sensitivity!$C$9 -> 1.5 | BD11: 1
A12: Multiplier - refunds, replacements, returns | B12: 1 | H12: 1 | N12: 1 | T12: 1 | Z12: 1 | AF12: 1 | AL12: 1 | AR12: 1 | AX12: 1 | BD12: =Sensitivity!$C$10 -> 2
A14: Landed cost build (per unit, value in first column of each group)
A15: Test-stage fountain landed (AliExpress x (1 + duty + AutoDS fee)) | B15: =Inputs!$G$25*$B$8*(1+Inputs!$G$26+Inputs!$G$27) -> 38.3265 | H15: =Inputs!$D$25*$H$8*(1+Inputs!$D$26+Inputs!$D$27) -> 48.564 | N15: =Inputs!$E$25*$N$8*(1+Inputs!$E$26+Inputs!$E$27) -> 38.3265 | T15: =Inputs!$F$25*$T$8*(1+Inputs!$F$26+Inputs!$F$27) -> 21.79 | Z15: =Inputs!$E$25*$Z$8*(1+Inputs!$E$26+Inputs!$E$27) -> 38.3265 | AF15: =Inputs!$E$25*$AF$8*(1+Inputs!$E$26+Inputs!$E$27) -> 44.075475 | AL15: =Inputs!$E$25*$AL$8*(1+Inputs!$E$26+Inputs!$E$27) -> 38.3265 | AR15: =Inputs!$E$25*$AR$8*(1+Inputs!$E$26+Inputs!$E$27) -> 38.3265 | AX15: =Inputs!$E$25*$AX$8*(1+Inputs!$E$26+Inputs!$E$27) -> 38.3265 | BD15: =Inputs!$E$25*$BD$8*(1+Inputs!$E$26+Inputs!$E$27) -> 38.3265
A16: PL fountain FOB incl. listed adapter | B16: =(Inputs!$G$36+Inputs!$G$37)*$B$8 -> 11.77 | H16: =(Inputs!$D$36+Inputs!$D$37)*$H$8 -> 13.83 | N16: =(Inputs!$E$36+Inputs!$E$37)*$N$8 -> 11.77 | T16: =(Inputs!$F$36+Inputs!$F$37)*$T$8 -> 8.16 | Z16: =(Inputs!$E$36+Inputs!$E$37)*$Z$8 -> 11.77 | AF16: =(Inputs!$E$36+Inputs!$E$37)*$AF$8 -> 13.5355 | AL16: =(Inputs!$E$36+Inputs!$E$37)*$AL$8 -> 11.77 | AR16: =(Inputs!$E$36+Inputs!$E$37)*$AR$8 -> 11.77 | AX16: =(Inputs!$E$36+Inputs!$E$37)*$AX$8 -> 11.77 | BD16: =(Inputs!$E$36+Inputs!$E$37)*$BD$8 -> 11.77
A17: PL duty (Section 301 stack) | B17: =$B$16*Inputs!$G$39 -> 4.41375 | H17: =$H$16*Inputs!$D$39 -> 5.18625 | N17: =$N$16*Inputs!$E$39 -> 4.41375 | T17: =$T$16*Inputs!$F$39 -> 3.06 | Z17: =$Z$16*Inputs!$E$39 -> 4.41375 | AF17: =$AF$16*Inputs!$E$39 -> 5.0758125 | AL17: =$AL$16*Inputs!$E$39 -> 4.41375 | AR17: =$AR$16*Inputs!$E$39 -> 4.41375 | AX17: =$AX$16*Inputs!$E$39 -> 4.41375 | BD17: =$BD$16*Inputs!$E$39 -> 4.41375
A18: PL ocean freight per unit | B18: =Inputs!$G$38 -> 3.5 | H18: =Inputs!$D$38 -> 5 | N18: =Inputs!$E$38 -> 3.5 | T18: =Inputs!$F$38 -> 2.2 | Z18: =Inputs!$E$38 -> 3.5 | AF18: =Inputs!$E$38 -> 3.5 | AL18: =Inputs!$E$38 -> 3.5 | AR18: =Inputs!$E$38 -> 3.5 | AX18: =Inputs!$E$38 -> 3.5 | BD18: =Inputs!$E$38 -> 3.5
A19: PL customs entry fees per unit (broker, ISF, bond, MPF, HMF) | B19: =(Inputs!$G$41+Inputs!$G$42+Inputs!$G$43+MAX(Inputs!$G$45,MIN(Inputs!$G$46,Inputs!$G$44*Inputs!$G$40*$B$16))+Inputs!$G$47*Inputs!$G$40*$B$16)/Inputs!$G$40 -> 0.6318725 | H19: =(Inputs!$D$41+Inputs!$D$42+Inputs!$D$43+MAX(Inputs!$D$45,MIN(Inputs!$D$46,Inputs!$D$44*Inputs!$D$40*$H$16))+Inputs!$D$47*Inputs!$D$40*$H$16)/Inputs!$D$40 -> 0.8844475 | N19: =(Inputs!$E$41+Inputs!$E$42+Inputs!$E$43+MAX(Inputs!$E$45,MIN(Inputs!$E$46,Inputs!$E$44*Inputs!$E$40*$N$16))+Inputs!$E$47*Inputs!$E$40*$N$16)/Inputs!$E$40 -> 0.6318725 | T19: =(Inputs!$F$41+Inputs!$F$42+Inputs!$F$43+MAX(Inputs!$F$45,MIN(Inputs!$F$46,Inputs!$F$44*Inputs!$F$40*$T$16))+Inputs!$F$47*Inputs!$F$40*$T$16)/Inputs!$F$40 -> 0.21378 | Z19: =(Inputs!$E$41+Inputs!$E$42+Inputs!$E$43+MAX(Inputs!$E$45,MIN(Inputs!$E$46,Inputs!$E$44*Inputs!$E$40*$Z$16))+Inputs!$E$47*Inputs!$E$40*$Z$16)/Inputs!$E$40 -> 0.6318725 | AF19: =(Inputs!$E$41+Inputs!$E$42+Inputs!$E$43+MAX(Inputs!$E$45,MIN(Inputs!$E$46,Inputs!$E$44*Inputs!$E$40*$AF$16))+Inputs!$E$47*Inputs!$E$40*$AF$16)/Inputs!$E$40 -> 0.63407937 | AL19: =(Inputs!$E$41+Inputs!$E$42+Inputs!$E$43+MAX(Inputs!$E$45,MIN(Inputs!$E$46,Inputs!$E$44*Inputs!$E$40*$AL$16))+Inputs!$E$47*Inputs!$E$40*$AL$16)/Inputs!$E$40 -> 0.6318725 | AR19: =(Inputs!$E$41+Inputs!$E$42+Inputs!$E$43+MAX(Inputs!$E$45,MIN(Inputs!$E$46,Inputs!$E$44*Inputs!$E$40*$AR$16))+Inputs!$E$47*Inputs!$E$40*$AR$16)/Inputs!$E$40 -> 0.6318725 | AX19: =(Inputs!$E$41+Inputs!$E$42+Inputs!$E$43+MAX(Inputs!$E$45,MIN(Inputs!$E$46,Inputs!$E$44*Inputs!$E$40*$AX$16))+Inputs!$E$47*Inputs!$E$40*$AX$16)/Inputs!$E$40 -> 0.6318725 | BD19: =(Inputs!$E$41+Inputs!$E$42+Inputs!$E$43+MAX(Inputs!$E$45,MIN(Inputs!$E$46,Inputs!$E$44*Inputs!$E$40*$BD$16))+Inputs!$E$47*Inputs!$E$40*$BD$16)/Inputs!$E$40 -> 0.6318725
A20: PL retail packaging | B20: =Inputs!$G$48 -> 1 | H20: =Inputs!$D$48 -> 1.5 | N20: =Inputs!$E$48 -> 1 | T20: =Inputs!$F$48 -> 0.7 | Z20: =Inputs!$E$48 -> 1 | AF20: =Inputs!$E$48 -> 1 | AL20: =Inputs!$E$48 -> 1 | AR20: =Inputs!$E$48 -> 1 | AX20: =Inputs!$E$48 -> 1 | BD20: =Inputs!$E$48 -> 1
A21: PL certification amortization (FCC + Prop 65 + food-contact) | B21: =(Inputs!$G$49+Inputs!$G$50+Inputs!$G$51)/Inputs!$G$52 -> 4.65 | H21: =(Inputs!$D$49+Inputs!$D$50+Inputs!$D$51)/Inputs!$D$52 -> 14.8 | N21: =(Inputs!$E$49+Inputs!$E$50+Inputs!$E$51)/Inputs!$E$52 -> 4.65 | T21: =(Inputs!$F$49+Inputs!$F$50+Inputs!$F$51)/Inputs!$F$52 -> 1.275 | Z21: =(Inputs!$E$49+Inputs!$E$50+Inputs!$E$51)/Inputs!$E$52 -> 4.65 | AF21: =(Inputs!$E$49+Inputs!$E$50+Inputs!$E$51)/Inputs!$E$52 -> 4.65 | AL21: =(Inputs!$E$49+Inputs!$E$50+Inputs!$E$51)/Inputs!$E$52 -> 4.65 | AR21: =(Inputs!$E$49+Inputs!$E$50+Inputs!$E$51)/Inputs!$E$52 -> 4.65 | AX21: =(Inputs!$E$49+Inputs!$E$50+Inputs!$E$51)/Inputs!$E$52 -> 4.65 | BD21: =(Inputs!$E$49+Inputs!$E$50+Inputs!$E$51)/Inputs!$E$52 -> 4.65
A22: PL fountain landed cost | B22: =SUM(B16:B21) -> 25.965622 | H22: =SUM(H16:H21) -> 41.200698 | N22: =SUM(N16:N21) -> 25.965622 | T22: =SUM(T16:T21) -> 15.60878 | Z22: =SUM(Z16:Z21) -> 25.965622 | AF22: =SUM(AF16:AF21) -> 28.395392 | AL22: =SUM(AL16:AL21) -> 25.965622 | AR22: =SUM(AR16:AR21) -> 25.965622 | AX22: =SUM(AX16:AX21) -> 25.965622 | BD22: =SUM(BD16:BD21) -> 25.965622
A23: PL litter mat landed cost | B23: =Inputs!$G$53*$B$8*(1+Inputs!$G$54)+Inputs!$G$55 -> 5.075 | H23: =Inputs!$D$53*$H$8*(1+Inputs!$D$54)+Inputs!$D$55 -> 6.7 | N23: =Inputs!$E$53*$N$8*(1+Inputs!$E$54)+Inputs!$E$55 -> 5.075 | T23: =Inputs!$F$53*$T$8*(1+Inputs!$F$54)+Inputs!$F$55 -> 3 | Z23: =Inputs!$E$53*$Z$8*(1+Inputs!$E$54)+Inputs!$E$55 -> 5.075 | AF23: =Inputs!$E$53*$AF$8*(1+Inputs!$E$54)+Inputs!$E$55 -> 5.71625 | AL23: =Inputs!$E$53*$AL$8*(1+Inputs!$E$54)+Inputs!$E$55 -> 5.075 | AR23: =Inputs!$E$53*$AR$8*(1+Inputs!$E$54)+Inputs!$E$55 -> 5.075 | AX23: =Inputs!$E$53*$AX$8*(1+Inputs!$E$54)+Inputs!$E$55 -> 5.075 | BD23: =Inputs!$E$53*$BD$8*(1+Inputs!$E$54)+Inputs!$E$55 -> 5.075
A24: PL filter 6-pack landed cost (US stock) | B24: =Inputs!$G$15*Inputs!$G$56*$B$8*(1+Inputs!$G$57)+Inputs!$G$58+Inputs!$G$59 -> 5.2425 | H24: =Inputs!$D$15*Inputs!$D$56*$H$8*(1+Inputs!$D$57)+Inputs!$D$58+Inputs!$D$59 -> 6.5675 | N24: =Inputs!$E$15*Inputs!$E$56*$N$8*(1+Inputs!$E$57)+Inputs!$E$58+Inputs!$E$59 -> 5.2425 | T24: =Inputs!$F$15*Inputs!$F$56*$T$8*(1+Inputs!$F$57)+Inputs!$F$58+Inputs!$F$59 -> 4.3625 | Z24: =Inputs!$E$15*Inputs!$E$56*$Z$8*(1+Inputs!$E$57)+Inputs!$E$58+Inputs!$E$59 -> 5.2425 | AF24: =Inputs!$E$15*Inputs!$E$56*$AF$8*(1+Inputs!$E$57)+Inputs!$E$58+Inputs!$E$59 -> 5.848875 | AL24: =Inputs!$E$15*Inputs!$E$56*$AL$8*(1+Inputs!$E$57)+Inputs!$E$58+Inputs!$E$59 -> 5.2425 | AR24: =Inputs!$E$15*Inputs!$E$56*$AR$8*(1+Inputs!$E$57)+Inputs!$E$58+Inputs!$E$59 -> 5.2425 | AX24: =Inputs!$E$15*Inputs!$E$56*$AX$8*(1+Inputs!$E$57)+Inputs!$E$58+Inputs!$E$59 -> 5.2425 | BD24: =Inputs!$E$15*Inputs!$E$56*$BD$8*(1+Inputs!$E$57)+Inputs!$E$58+Inputs!$E$59 -> 5.2425
A26: Order type | B26: (a) Fountain first order - TEST stage (AliExpress) | C26: (b) Fountain first order - PRIVATE LABEL | D26: (c) Fountain + litter mat bundle - PRIVATE LABEL | E26: (d) Filter 90-day pack - SUBSCRIPTION renewal | F26: (e) Filter pack - one-time repeat order | H26: (a) Fountain first order - TEST stage (AliExpress) | I26: (b) Fountain first order - PRIVATE LABEL | J26: (c) Fountain + litter mat bundle - PRIVATE LABEL | K26: (d) Filter 90-day pack - SUBSCRIPTION renewal | L26: (e) Filter pack - one-time repeat order | N26: (a) Fountain first order - TEST stage (AliExpress) | O26: (b) Fountain first order - PRIVATE LABEL | P26: (c) Fountain + litter mat bundle - PRIVATE LABEL | Q26: (d) Filter 90-day pack - SUBSCRIPTION renewal | R26: (e) Filter pack - one-time repeat order | T26: (a) Fountain first order - TEST stage (AliExpress) | U26: (b) Fountain first order - PRIVATE LABEL | V26: (c) Fountain + litter mat bundle - PRIVATE LABEL | W26: (d) Filter 90-day pack - SUBSCRIPTION renewal | X26: (e) Filter pack - one-time repeat order | Z26: (a) Fountain first order - TEST stage (AliExpress) | AA26: (b) Fountain first order - PRIVATE LABEL | AB26: (c) Fountain + litter mat bundle - PRIVATE LABEL | AC26: (d) Filter 90-day pack - SUBSCRIPTION renewal | AD26: (e) Filter pack - one-time repeat order | AF26: (a) Fountain first order - TEST stage (AliExpress) | AG26: (b) Fountain first order - PRIVATE LABEL | AH26: (c) Fountain + litter mat bundle - PRIVATE LABEL | AI26: (d) Filter 90-day pack - SUBSCRIPTION renewal | AJ26: (e) Filter pack - one-time repeat order | AL26: (a) Fountain first order - TEST stage (AliExpress) | AM26: (b) Fountain first order - PRIVATE LABEL | AN26: (c) Fountain + litter mat bundle - PRIVATE LABEL | AO26: (d) Filter 90-day pack - SUBSCRIPTION renewal | AP26: (e) Filter pack - one-time repeat order | AR26: (a) Fountain first order - TEST stage (AliExpress) | AS26: (b) Fountain first order - PRIVATE LABEL | AT26: (c) Fountain + litter mat bundle - PRIVATE LABEL | AU26: (d) Filter 90-day pack - SUBSCRIPTION renewal | AV26: (e) Filter pack - one-time repeat order | AX26: (a) Fountain first order - TEST stage (AliExpress) | AY26: (b) Fountain first order - PRIVATE LABEL | AZ26: (c) Fountain + litter mat bundle - PRIVATE LABEL | BA26: (d) Filter 90-day pack - SUBSCRIPTION renewal | BB26: (e) Filter pack - one-time repeat order | BD26: (a) Fountain first order - TEST stage (AliExpress) | BE26: (b) Fountain first order - PRIVATE LABEL | BF26: (c) Fountain + litter mat bundle - PRIVATE LABEL | BG26: (d) Filter 90-day pack - SUBSCRIPTION renewal | BH26: (e) Filter pack - one-time repeat order
A27: Stage | B27: Test | C27: Private label | D27: Private label | E27: PL renewal | F27: PL one-time | H27: Test | I27: Private label | J27: Private label | K27: PL renewal | L27: PL one-time | N27: Test | O27: Private label | P27: Private label | Q27: PL renewal | R27: PL one-time | T27: Test | U27: Private label | V27: Private label | W27: PL renewal | X27: PL one-time | Z27: Test | AA27: Private label | AB27: Private label | AC27: PL renewal | AD27: PL one-time | AF27: Test | AG27: Private label | AH27: Private label | AI27: PL renewal | AJ27: PL one-time | AL27: Test | AM27: Private label | AN27: Private label | AO27: PL renewal | AP27: PL one-time | AR27: Test | AS27: Private label | AT27: Private label | AU27: PL renewal | AV27: PL one-time | AX27: Test | AY27: Private label | AZ27: Private label | BA27: PL renewal | BB27: PL one-time | BD27: Test | BE27: Private label | BF27: Private label | BG27: PL renewal | BH27: PL one-time
A28: Fountain units | B28: 1 | C28: 1 | D28: 1 | E28: 0 | F28: 0 | H28: 1 | I28: 1 | J28: 1 | K28: 0 | L28: 0 | N28: 1 | O28: 1 | P28: 1 | Q28: 0 | R28: 0 | T28: 1 | U28: 1 | V28: 1 | W28: 0 | X28: 0 | Z28: 1 | AA28: 1 | AB28: 1 | AC28: 0 | AD28: 0 | AF28: 1 | AG28: 1 | AH28: 1 | AI28: 0 | AJ28: 0 | AL28: 1 | AM28: 1 | AN28: 1 | AO28: 0 | AP28: 0 | AR28: 1 | AS28: 1 | AT28: 1 | AU28: 0 | AV28: 0 | AX28: 1 | AY28: 1 | AZ28: 1 | BA28: 0 | BB28: 0 | BD28: 1 | BE28: 1 | BF28: 1 | BG28: 0 | BH28: 0
A29: Litter mat units | B29: 0 | C29: 0 | D29: 1 | E29: 0 | F29: 0 | H29: 0 | I29: 0 | J29: 1 | K29: 0 | L29: 0 | N29: 0 | O29: 0 | P29: 1 | Q29: 0 | R29: 0 | T29: 0 | U29: 0 | V29: 1 | W29: 0 | X29: 0 | Z29: 0 | AA29: 0 | AB29: 1 | AC29: 0 | AD29: 0 | AF29: 0 | AG29: 0 | AH29: 1 | AI29: 0 | AJ29: 0 | AL29: 0 | AM29: 0 | AN29: 1 | AO29: 0 | AP29: 0 | AR29: 0 | AS29: 0 | AT29: 1 | AU29: 0 | AV29: 0 | AX29: 0 | AY29: 0 | AZ29: 1 | BA29: 0 | BB29: 0 | BD29: 0 | BE29: 0 | BF29: 1 | BG29: 0 | BH29: 0
A30: Filter packs | B30: 0 | C30: 0 | D30: 0 | E30: 1 | F30: 1 | H30: 0 | I30: 0 | J30: 0 | K30: 1 | L30: 1 | N30: 0 | O30: 0 | P30: 0 | Q30: 1 | R30: 1 | T30: 0 | U30: 0 | V30: 0 | W30: 1 | X30: 1 | Z30: 0 | AA30: 0 | AB30: 0 | AC30: 1 | AD30: 1 | AF30: 0 | AG30: 0 | AH30: 0 | AI30: 1 | AJ30: 1 | AL30: 0 | AM30: 0 | AN30: 0 | AO30: 1 | AP30: 1 | AR30: 0 | AS30: 0 | AT30: 0 | AU30: 1 | AV30: 1 | AX30: 0 | AY30: 0 | AZ30: 0 | BA30: 1 | BB30: 1 | BD30: 0 | BE30: 0 | BF30: 0 | BG30: 1 | BH30: 1
A31: Revenue - fountain | B31: =B28*Inputs!$G$11 -> 49.99 | C31: =C28*Inputs!$G$11 -> 49.99 | D31: =D28*Inputs!$G$11 -> 49.99 | E31: =E28*Inputs!$G$11 -> 0 | F31: =F28*Inputs!$G$11 -> 0 | H31: =H28*Inputs!$D$11 -> 44.99 | I31: =I28*Inputs!$D$11 -> 44.99 | J31: =J28*Inputs!$D$11 -> 44.99 | K31: =K28*Inputs!$D$11 -> 0 | L31: =L28*Inputs!$D$11 -> 0 | N31: =N28*Inputs!$E$11 -> 49.99 | O31: =O28*Inputs!$E$11 -> 49.99 | P31: =P28*Inputs!$E$11 -> 49.99 | Q31: =Q28*Inputs!$E$11 -> 0 | R31: =R28*Inputs!$E$11 -> 0 | T31: =T28*Inputs!$F$11 -> 59.99 | U31: =U28*Inputs!$F$11 -> 59.99 | V31: =V28*Inputs!$F$11 -> 59.99 | W31: =W28*Inputs!$F$11 -> 0 | X31: =X28*Inputs!$F$11 -> 0 | Z31: =Z28*Inputs!$E$11 -> 49.99 | AA31: =AA28*Inputs!$E$11 -> 49.99 | AB31: =AB28*Inputs!$E$11 -> 49.99 | AC31: =AC28*Inputs!$E$11 -> 0 | AD31: =AD28*Inputs!$E$11 -> 0 | AF31: =AF28*Inputs!$E$11 -> 49.99 | AG31: =AG28*Inputs!$E$11 -> 49.99 | AH31: =AH28*Inputs!$E$11 -> 49.99 | AI31: =AI28*Inputs!$E$11 -> 0 | AJ31: =AJ28*Inputs!$E$11 -> 0 | AL31: =AL28*Inputs!$E$11 -> 49.99 | AM31: =AM28*Inputs!$E$11 -> 49.99 | AN31: =AN28*Inputs!$E$11 -> 49.99 | AO31: =AO28*Inputs!$E$11 -> 0 | AP31: =AP28*Inputs!$E$11 -> 0 | AR31: =AR28*Inputs!$E$11 -> 49.99 | AS31: =AS28*Inputs!$E$11 -> 49.99 | AT31: =AT28*Inputs!$E$11 -> 49.99 | AU31: =AU28*Inputs!$E$11 -> 0 | AV31: =AV28*Inputs!$E$11 -> 0 | AX31: =AX28*Inputs!$E$11 -> 49.99 | AY31: =AY28*Inputs!$E$11 -> 49.99 | AZ31: =AZ28*Inputs!$E$11 -> 49.99 | BA31: =BA28*Inputs!$E$11 -> 0 | BB31: =BB28*Inputs!$E$11 -> 0 | BD31: =BD28*Inputs!$E$11 -> 49.99 | BE31: =BE28*Inputs!$E$11 -> 49.99 | BF31: =BF28*Inputs!$E$11 -> 49.99 | BG31: =BG28*Inputs!$E$11 -> 0 | BH31: =BH28*Inputs!$E$11 -> 0
A32: Revenue - litter mat | B32: =B29*Inputs!$G$17 -> 0 | C32: =C29*Inputs!$G$17 -> 0 | D32: =D29*Inputs!$G$17 -> 19.99 | E32: =E29*Inputs!$G$17 -> 0 | F32: =F29*Inputs!$G$17 -> 0 | H32: =H29*Inputs!$D$17 -> 0 | I32: =I29*Inputs!$D$17 -> 0 | J32: =J29*Inputs!$D$17 -> 16.99 | K32: =K29*Inputs!$D$17 -> 0 | L32: =L29*Inputs!$D$17 -> 0 | N32: =N29*Inputs!$E$17 -> 0 | O32: =O29*Inputs!$E$17 -> 0 | P32: =P29*Inputs!$E$17 -> 19.99 | Q32: =Q29*Inputs!$E$17 -> 0 | R32: =R29*Inputs!$E$17 -> 0 | T32: =T29*Inputs!$F$17 -> 0 | U32: =U29*Inputs!$F$17 -> 0 | V32: =V29*Inputs!$F$17 -> 22.99 | W32: =W29*Inputs!$F$17 -> 0 | X32: =X29*Inputs!$F$17 -> 0 | Z32: =Z29*Inputs!$E$17 -> 0 | AA32: =AA29*Inputs!$E$17 -> 0 | AB32: =AB29*Inputs!$E$17 -> 19.99 | AC32: =AC29*Inputs!$E$17 -> 0 | AD32: =AD29*Inputs!$E$17 -> 0 | AF32: =AF29*Inputs!$E$17 -> 0 | AG32: =AG29*Inputs!$E$17 -> 0 | AH32: =AH29*Inputs!$E$17 -> 19.99 | AI32: =AI29*Inputs!$E$17 -> 0 | AJ32: =AJ29*Inputs!$E$17 -> 0 | AL32: =AL29*Inputs!$E$17 -> 0 | AM32: =AM29*Inputs!$E$17 -> 0 | AN32: =AN29*Inputs!$E$17 -> 19.99 | AO32: =AO29*Inputs!$E$17 -> 0 | AP32: =AP29*Inputs!$E$17 -> 0 | AR32: =AR29*Inputs!$E$17 -> 0 | AS32: =AS29*Inputs!$E$17 -> 0 | AT32: =AT29*Inputs!$E$17 -> 19.99 | AU32: =AU29*Inputs!$E$17 -> 0 | AV32: =AV29*Inputs!$E$17 -> 0 | AX32: =AX29*Inputs!$E$17 -> 0 | AY32: =AY29*Inputs!$E$17 -> 0 | AZ32: =AZ29*Inputs!$E$17 -> 19.99 | BA32: =BA29*Inputs!$E$17 -> 0 | BB32: =BB29*Inputs!$E$17 -> 0 | BD32: =BD29*Inputs!$E$17 -> 0 | BE32: =BE29*Inputs!$E$17 -> 0 | BF32: =BF29*Inputs!$E$17 -> 19.99 | BG32: =BG29*Inputs!$E$17 -> 0 | BH32: =BH29*Inputs!$E$17 -> 0
A33: Revenue - filter pack | B33: =B30*Inputs!$G$14 -> 0 | C33: =C30*Inputs!$G$14 -> 0 | D33: =D30*Inputs!$G$14 -> 0 | E33: =E30*Inputs!$G$14 -> 15.291 | F33: =F30*Inputs!$G$12 -> 16.99 | H33: =H30*Inputs!$D$14 -> 0 | I33: =I30*Inputs!$D$14 -> 0 | J33: =J30*Inputs!$D$14 -> 0 | K33: =K30*Inputs!$D$14 -> 12.7415 | L33: =L30*Inputs!$D$12 -> 14.99 | N33: =N30*Inputs!$E$14 -> 0 | O33: =O30*Inputs!$E$14 -> 0 | P33: =P30*Inputs!$E$14 -> 0 | Q33: =Q30*Inputs!$E$14 -> 15.291 | R33: =R30*Inputs!$E$12 -> 16.99 | T33: =T30*Inputs!$F$14 -> 0 | U33: =U30*Inputs!$F$14 -> 0 | V33: =V30*Inputs!$F$14 -> 0 | W33: =W30*Inputs!$F$14 -> 15.741 | X33: =X30*Inputs!$F$12 -> 17.49 | Z33: =Z30*Inputs!$E$14 -> 0 | AA33: =AA30*Inputs!$E$14 -> 0 | AB33: =AB30*Inputs!$E$14 -> 0 | AC33: =AC30*Inputs!$E$14 -> 15.291 | AD33: =AD30*Inputs!$E$12 -> 16.99 | AF33: =AF30*Inputs!$E$14 -> 0 | AG33: =AG30*Inputs!$E$14 -> 0 | AH33: =AH30*Inputs!$E$14 -> 0 | AI33: =AI30*Inputs!$E$14 -> 15.291 | AJ33: =AJ30*Inputs!$E$12 -> 16.99 | AL33: =AL30*Inputs!$E$14 -> 0 | AM33: =AM30*Inputs!$E$14 -> 0 | AN33: =AN30*Inputs!$E$14 -> 0 | AO33: =AO30*Inputs!$E$14 -> 15.291 | AP33: =AP30*Inputs!$E$12 -> 16.99 | AR33: =AR30*Inputs!$E$14 -> 0 | AS33: =AS30*Inputs!$E$14 -> 0 | AT33: =AT30*Inputs!$E$14 -> 0 | AU33: =AU30*Inputs!$E$14 -> 15.291 | AV33: =AV30*Inputs!$E$12 -> 16.99 | AX33: =AX30*Inputs!$E$14 -> 0 | AY33: =AY30*Inputs!$E$14 -> 0 | AZ33: =AZ30*Inputs!$E$14 -> 0 | BA33: =BA30*Inputs!$E$14 -> 15.291 | BB33: =BB30*Inputs!$E$12 -> 16.99 | BD33: =BD30*Inputs!$E$14 -> 0 | BE33: =BE30*Inputs!$E$14 -> 0 | BF33: =BF30*Inputs!$E$14 -> 0 | BG33: =BG30*Inputs!$E$14 -> 15.291 | BH33: =BH30*Inputs!$E$12 -> 16.99
A34: Shipping charged to customer | B34: 0 | C34: 0 | D34: 0 | E34: 0 | F34: =Inputs!$G$16 -> 0 | H34: 0 | I34: 0 | J34: 0 | K34: 0 | L34: =Inputs!$D$16 -> 0 | N34: 0 | O34: 0 | P34: 0 | Q34: 0 | R34: =Inputs!$E$16 -> 0 | T34: 0 | U34: 0 | V34: 0 | W34: 0 | X34: =Inputs!$F$16 -> 3.99 | Z34: 0 | AA34: 0 | AB34: 0 | AC34: 0 | AD34: =Inputs!$E$16 -> 0 | AF34: 0 | AG34: 0 | AH34: 0 | AI34: 0 | AJ34: =Inputs!$E$16 -> 0 | AL34: 0 | AM34: 0 | AN34: 0 | AO34: 0 | AP34: =Inputs!$E$16 -> 0 | AR34: 0 | AS34: 0 | AT34: 0 | AU34: 0 | AV34: =Inputs!$E$16 -> 0 | AX34: 0 | AY34: 0 | AZ34: 0 | BA34: 0 | BB34: =Inputs!$E$16 -> 0 | BD34: 0 | BE34: 0 | BF34: 0 | BG34: 0 | BH34: =Inputs!$E$16 -> 0
A35: Gross revenue | B35: =SUM(B31:B34) -> 49.99 | C35: =SUM(C31:C34) -> 49.99 | D35: =SUM(D31:D34) -> 69.98 | E35: =SUM(E31:E34) -> 15.291 | F35: =SUM(F31:F34) -> 16.99 | H35: =SUM(H31:H34) -> 44.99 | I35: =SUM(I31:I34) -> 44.99 | J35: =SUM(J31:J34) -> 61.98 | K35: =SUM(K31:K34) -> 12.7415 | L35: =SUM(L31:L34) -> 14.99 | N35: =SUM(N31:N34) -> 49.99 | O35: =SUM(O31:O34) -> 49.99 | P35: =SUM(P31:P34) -> 69.98 | Q35: =SUM(Q31:Q34) -> 15.291 | R35: =SUM(R31:R34) -> 16.99 | T35: =SUM(T31:T34) -> 59.99 | U35: =SUM(U31:U34) -> 59.99 | V35: =SUM(V31:V34) -> 82.98 | W35: =SUM(W31:W34) -> 15.741 | X35: =SUM(X31:X34) -> 21.48 | Z35: =SUM(Z31:Z34) -> 49.99 | AA35: =SUM(AA31:AA34) -> 49.99 | AB35: =SUM(AB31:AB34) -> 69.98 | AC35: =SUM(AC31:AC34) -> 15.291 | AD35: =SUM(AD31:AD34) -> 16.99 | AF35: =SUM(AF31:AF34) -> 49.99 | AG35: =SUM(AG31:AG34) -> 49.99 | AH35: =SUM(AH31:AH34) -> 69.98 | AI35: =SUM(AI31:AI34) -> 15.291 | AJ35: =SUM(AJ31:AJ34) -> 16.99 | AL35: =SUM(AL31:AL34) -> 49.99 | AM35: =SUM(AM31:AM34) -> 49.99 | AN35: =SUM(AN31:AN34) -> 69.98 | AO35: =SUM(AO31:AO34) -> 15.291 | AP35: =SUM(AP31:AP34) -> 16.99 | AR35: =SUM(AR31:AR34) -> 49.99 | AS35: =SUM(AS31:AS34) -> 49.99 | AT35: =SUM(AT31:AT34) -> 69.98 | AU35: =SUM(AU31:AU34) -> 15.291 | AV35: =SUM(AV31:AV34) -> 16.99 | AX35: =SUM(AX31:AX34) -> 49.99 | AY35: =SUM(AY31:AY34) -> 49.99 | AZ35: =SUM(AZ31:AZ34) -> 69.98 | BA35: =SUM(BA31:BA34) -> 15.291 | BB35: =SUM(BB31:BB34) -> 16.99 | BD35: =SUM(BD31:BD34) -> 49.99 | BE35: =SUM(BE31:BE34) -> 49.99 | BF35: =SUM(BF31:BF34) -> 69.98 | BG35: =SUM(BG31:BG34) -> 15.291 | BH35: =SUM(BH31:BH34) -> 16.99
A36: Refunds / returns (revenue reversed) | B36: =-(B31*Inputs!$G$102+(B32+B33)*Inputs!$G$104)*$B$12 -> -2.4995 | C36: =-(C31*Inputs!$G$102+(C32+C33)*Inputs!$G$104)*$B$12 -> -2.4995 | D36: =-(D31*Inputs!$G$102+(D32+D33)*Inputs!$G$104)*$B$12 -> -2.6994 | E36: =-(E31*Inputs!$G$102+(E32+E33)*Inputs!$G$104)*$B$12 -> -0.15291 | F36: =-(F31*Inputs!$G$102+(F32+F33)*Inputs!$G$104)*$B$12 -> -0.1699 | H36: =-(H31*Inputs!$D$102+(H32+H33)*Inputs!$D$104)*$H$12 -> -3.5992 | I36: =-(I31*Inputs!$D$102+(I32+I33)*Inputs!$D$104)*$H$12 -> -3.5992 | J36: =-(J31*Inputs!$D$102+(J32+J33)*Inputs!$D$104)*$H$12 -> -3.939 | K36: =-(K31*Inputs!$D$102+(K32+K33)*Inputs!$D$104)*$H$12 -> -0.25483 | L36: =-(L31*Inputs!$D$102+(L32+L33)*Inputs!$D$104)*$H$12 -> -0.2998 | N36: =-(N31*Inputs!$E$102+(N32+N33)*Inputs!$E$104)*$N$12 -> -2.4995 | O36: =-(O31*Inputs!$E$102+(O32+O33)*Inputs!$E$104)*$N$12 -> -2.4995 | P36: =-(P31*Inputs!$E$102+(P32+P33)*Inputs!$E$104)*$N$12 -> -2.6994 | Q36: =-(Q31*Inputs!$E$102+(Q32+Q33)*Inputs!$E$104)*$N$12 -> -0.15291 | R36: =-(R31*Inputs!$E$102+(R32+R33)*Inputs!$E$104)*$N$12 -> -0.1699 | T36: =-(T31*Inputs!$F$102+(T32+T33)*Inputs!$F$104)*$T$12 -> -1.7997 | U36: =-(U31*Inputs!$F$102+(U32+U33)*Inputs!$F$104)*$T$12 -> -1.7997 | V36: =-(V31*Inputs!$F$102+(V32+V33)*Inputs!$F$104)*$T$12 -> -1.91465 | W36: =-(W31*Inputs!$F$102+(W32+W33)*Inputs!$F$104)*$T$12 -> -0.078705 | X36: =-(X31*Inputs!$F$102+(X32+X33)*Inputs!$F$104)*$T$12 -> -0.08745 | Z36: =-(Z31*Inputs!$E$102+(Z32+Z33)*Inputs!$E$104)*$Z$12 -> -2.4995 | AA36: =-(AA31*Inputs!$E$102+(AA32+AA33)*Inputs!$E$104)*$Z$12 -> -2.4995 | AB36: =-(AB31*Inputs!$E$102+(AB32+AB33)*Inputs!$E$104)*$Z$12 -> -2.6994 | AC36: =-(AC31*Inputs!$E$102+(AC32+AC33)*Inputs!$E$104)*$Z$12 -> -0.15291 | AD36: =-(AD31*Inputs!$E$102+(AD32+AD33)*Inputs!$E$104)*$Z$12 -> -0.1699 | AF36: =-(AF31*Inputs!$E$102+(AF32+AF33)*Inputs!$E$104)*$AF$12 -> -2.4995 | AG36: =-(AG31*Inputs!$E$102+(AG32+AG33)*Inputs!$E$104)*$AF$12 -> -2.4995 | AH36: =-(AH31*Inputs!$E$102+(AH32+AH33)*Inputs!$E$104)*$AF$12 -> -2.6994 | AI36: =-(AI31*Inputs!$E$102+(AI32+AI33)*Inputs!$E$104)*$AF$12 -> -0.15291 | AJ36: =-(AJ31*Inputs!$E$102+(AJ32+AJ33)*Inputs!$E$104)*$AF$12 -> -0.1699 | AL36: =-(AL31*Inputs!$E$102+(AL32+AL33)*Inputs!$E$104)*$AL$12 -> -2.4995 | AM36: =-(AM31*Inputs!$E$102+(AM32+AM33)*Inputs!$E$104)*$AL$12 -> -2.4995 | AN36: =-(AN31*Inputs!$E$102+(AN32+AN33)*Inputs!$E$104)*$AL$12 -> -2.6994 | AO36: =-(AO31*Inputs!$E$102+(AO32+AO33)*Inputs!$E$104)*$AL$12 -> -0.15291 | AP36: =-(AP31*Inputs!$E$102+(AP32+AP33)*Inputs!$E$104)*$AL$12 -> -0.1699 | AR36: =-(AR31*Inputs!$E$102+(AR32+AR33)*Inputs!$E$104)*$AR$12 -> -2.4995 | AS36: =-(AS31*Inputs!$E$102+(AS32+AS33)*Inputs!$E$104)*$AR$12 -> -2.4995 | AT36: =-(AT31*Inputs!$E$102+(AT32+AT33)*Inputs!$E$104)*$AR$12 -> -2.6994 | AU36: =-(AU31*Inputs!$E$102+(AU32+AU33)*Inputs!$E$104)*$AR$12 -> -0.15291 | AV36: =-(AV31*Inputs!$E$102+(AV32+AV33)*Inputs!$E$104)*$AR$12 -> -0.1699 | AX36: =-(AX31*Inputs!$E$102+(AX32+AX33)*Inputs!$E$104)*$AX$12 -> -2.4995 | AY36: =-(AY31*Inputs!$E$102+(AY32+AY33)*Inputs!$E$104)*$AX$12 -> -2.4995 | AZ36: =-(AZ31*Inputs!$E$102+(AZ32+AZ33)*Inputs!$E$104)*$AX$12 -> -2.6994 | BA36: =-(BA31*Inputs!$E$102+(BA32+BA33)*Inputs!$E$104)*$AX$12 -> -0.15291 | BB36: =-(BB31*Inputs!$E$102+(BB32+BB33)*Inputs!$E$104)*$AX$12 -> -0.1699 | BD36: =-(BD31*Inputs!$E$102+(BD32+BD33)*Inputs!$E$104)*$BD$12 -> -4.999 | BE36: =-(BE31*Inputs!$E$102+(BE32+BE33)*Inputs!$E$104)*$BD$12 -> -4.999 | BF36: =-(BF31*Inputs!$E$102+(BF32+BF33)*Inputs!$E$104)*$BD$12 -> -5.3988 | BG36: =-(BG31*Inputs!$E$102+(BG32+BG33)*Inputs!$E$104)*$BD$12 -> -0.30582 | BH36: =-(BH31*Inputs!$E$102+(BH32+BH33)*Inputs!$E$104)*$BD$12 -> -0.3398
A37: Net revenue | B37: =B35+B36 -> 47.4905 | C37: =C35+C36 -> 47.4905 | D37: =D35+D36 -> 67.2806 | E37: =E35+E36 -> 15.13809 | F37: =F35+F36 -> 16.8201 | H37: =H35+H36 -> 41.3908 | I37: =I35+I36 -> 41.3908 | J37: =J35+J36 -> 58.041 | K37: =K35+K36 -> 12.48667 | L37: =L35+L36 -> 14.6902 | N37: =N35+N36 -> 47.4905 | O37: =O35+O36 -> 47.4905 | P37: =P35+P36 -> 67.2806 | Q37: =Q35+Q36 -> 15.13809 | R37: =R35+R36 -> 16.8201 | T37: =T35+T36 -> 58.1903 | U37: =U35+U36 -> 58.1903 | V37: =V35+V36 -> 81.06535 | W37: =W35+W36 -> 15.662295 | X37: =X35+X36 -> 21.39255 | Z37: =Z35+Z36 -> 47.4905 | AA37: =AA35+AA36 -> 47.4905 | AB37: =AB35+AB36 -> 67.2806 | AC37: =AC35+AC36 -> 15.13809 | AD37: =AD35+AD36 -> 16.8201 | AF37: =AF35+AF36 -> 47.4905 | AG37: =AG35+AG36 -> 47.4905 | AH37: =AH35+AH36 -> 67.2806 | AI37: =AI35+AI36 -> 15.13809 | AJ37: =AJ35+AJ36 -> 16.8201 | AL37: =AL35+AL36 -> 47.4905 | AM37: =AM35+AM36 -> 47.4905 | AN37: =AN35+AN36 -> 67.2806 | AO37: =AO35+AO36 -> 15.13809 | AP37: =AP35+AP36 -> 16.8201 | AR37: =AR35+AR36 -> 47.4905 | AS37: =AS35+AS36 -> 47.4905 | AT37: =AT35+AT36 -> 67.2806 | AU37: =AU35+AU36 -> 15.13809 | AV37: =AV35+AV36 -> 16.8201 | AX37: =AX35+AX36 -> 47.4905 | AY37: =AY35+AY36 -> 47.4905 | AZ37: =AZ35+AZ36 -> 67.2806 | BA37: =BA35+BA36 -> 15.13809 | BB37: =BB35+BB36 -> 16.8201 | BD37: =BD35+BD36 -> 44.991 | BE37: =BE35+BE36 -> 44.991 | BF37: =BF35+BF36 -> 64.5812 | BG37: =BG35+BG36 -> 14.98518 | BH37: =BH35+BH36 -> 16.6502
A38: Product cost - fountain | B38: =-B28*$B$15 -> -38.3265 | C38: =-C28*$B$22 -> -25.965622 | D38: =-D28*$B$22 -> -25.965622 | E38: =-E28*$B$22 -> 0 | F38: =-F28*$B$22 -> 0 | H38: =-H28*$H$15 -> -48.564 | I38: =-I28*$H$22 -> -41.200698 | J38: =-J28*$H$22 -> -41.200698 | K38: =-K28*$H$22 -> 0 | L38: =-L28*$H$22 -> 0 | N38: =-N28*$N$15 -> -38.3265 | O38: =-O28*$N$22 -> -25.965622 | P38: =-P28*$N$22 -> -25.965622 | Q38: =-Q28*$N$22 -> 0 | R38: =-R28*$N$22 -> 0 | T38: =-T28*$T$15 -> -21.79 | U38: =-U28*$T$22 -> -15.60878 | V38: =-V28*$T$22 -> -15.60878 | W38: =-W28*$T$22 -> 0 | X38: =-X28*$T$22 -> 0 | Z38: =-Z28*$Z$15 -> -38.3265 | AA38: =-AA28*$Z$22 -> -25.965622 | AB38: =-AB28*$Z$22 -> -25.965622 | AC38: =-AC28*$Z$22 -> 0 | AD38: =-AD28*$Z$22 -> 0 | AF38: =-AF28*$AF$15 -> -44.075475 | AG38: =-AG28*$AF$22 -> -28.395392 | AH38: =-AH28*$AF$22 -> -28.395392 | AI38: =-AI28*$AF$22 -> 0 | AJ38: =-AJ28*$AF$22 -> 0 | AL38: =-AL28*$AL$15 -> -38.3265 | AM38: =-AM28*$AL$22 -> -25.965622 | AN38: =-AN28*$AL$22 -> -25.965622 | AO38: =-AO28*$AL$22 -> 0 | AP38: =-AP28*$AL$22 -> 0 | AR38: =-AR28*$AR$15 -> -38.3265 | AS38: =-AS28*$AR$22 -> -25.965622 | AT38: =-AT28*$AR$22 -> -25.965622 | AU38: =-AU28*$AR$22 -> 0 | AV38: =-AV28*$AR$22 -> 0 | AX38: =-AX28*$AX$15 -> -38.3265 | AY38: =-AY28*$AX$22 -> -25.965622 | AZ38: =-AZ28*$AX$22 -> -25.965622 | BA38: =-BA28*$AX$22 -> 0 | BB38: =-BB28*$AX$22 -> 0 | BD38: =-BD28*$BD$15 -> -38.3265 | BE38: =-BE28*$BD$22 -> -25.965622 | BF38: =-BF28*$BD$22 -> -25.965622 | BG38: =-BG28*$BD$22 -> 0 | BH38: =-BH28*$BD$22 -> 0
A39: Product cost - litter mat | B39: =-B29*$B$23 -> 0 | C39: =-C29*$B$23 -> 0 | D39: =-D29*$B$23 -> -5.075 | E39: =-E29*$B$23 -> 0 | F39: =-F29*$B$23 -> 0 | H39: =-H29*$H$23 -> 0 | I39: =-I29*$H$23 -> 0 | J39: =-J29*$H$23 -> -6.7 | K39: =-K29*$H$23 -> 0 | L39: =-L29*$H$23 -> 0 | N39: =-N29*$N$23 -> 0 | O39: =-O29*$N$23 -> 0 | P39: =-P29*$N$23 -> -5.075 | Q39: =-Q29*$N$23 -> 0 | R39: =-R29*$N$23 -> 0 | T39: =-T29*$T$23 -> 0 | U39: =-U29*$T$23 -> 0 | V39: =-V29*$T$23 -> -3 | W39: =-W29*$T$23 -> 0 | X39: =-X29*$T$23 -> 0 | Z39: =-Z29*$Z$23 -> 0 | AA39: =-AA29*$Z$23 -> 0 | AB39: =-AB29*$Z$23 -> -5.075 | AC39: =-AC29*$Z$23 -> 0 | AD39: =-AD29*$Z$23 -> 0 | AF39: =-AF29*$AF$23 -> 0 | AG39: =-AG29*$AF$23 -> 0 | AH39: =-AH29*$AF$23 -> -5.71625 | AI39: =-AI29*$AF$23 -> 0 | AJ39: =-AJ29*$AF$23 -> 0 | AL39: =-AL29*$AL$23 -> 0 | AM39: =-AM29*$AL$23 -> 0 | AN39: =-AN29*$AL$23 -> -5.075 | AO39: =-AO29*$AL$23 -> 0 | AP39: =-AP29*$AL$23 -> 0 | AR39: =-AR29*$AR$23 -> 0 | AS39: =-AS29*$AR$23 -> 0 | AT39: =-AT29*$AR$23 -> -5.075 | AU39: =-AU29*$AR$23 -> 0 | AV39: =-AV29*$AR$23 -> 0 | AX39: =-AX29*$AX$23 -> 0 | AY39: =-AY29*$AX$23 -> 0 | AZ39: =-AZ29*$AX$23 -> -5.075 | BA39: =-BA29*$AX$23 -> 0 | BB39: =-BB29*$AX$23 -> 0 | BD39: =-BD29*$BD$23 -> 0 | BE39: =-BE29*$BD$23 -> 0 | BF39: =-BF29*$BD$23 -> -5.075 | BG39: =-BG29*$BD$23 -> 0 | BH39: =-BH29*$BD$23 -> 0
A40: Product cost - filters | B40: =-B30*$B$24 -> 0 | C40: =-C30*$B$24 -> 0 | D40: =-D30*$B$24 -> 0 | E40: =-E30*$B$24 -> -5.2425 | F40: =-F30*$B$24 -> -5.2425 | H40: =-H30*$H$24 -> 0 | I40: =-I30*$H$24 -> 0 | J40: =-J30*$H$24 -> 0 | K40: =-K30*$H$24 -> -6.5675 | L40: =-L30*$H$24 -> -6.5675 | N40: =-N30*$N$24 -> 0 | O40: =-O30*$N$24 -> 0 | P40: =-P30*$N$24 -> 0 | Q40: =-Q30*$N$24 -> -5.2425 | R40: =-R30*$N$24 -> -5.2425 | T40: =-T30*$T$24 -> 0 | U40: =-U30*$T$24 -> 0 | V40: =-V30*$T$24 -> 0 | W40: =-W30*$T$24 -> -4.3625 | X40: =-X30*$T$24 -> -4.3625 | Z40: =-Z30*$Z$24 -> 0 | AA40: =-AA30*$Z$24 -> 0 | AB40: =-AB30*$Z$24 -> 0 | AC40: =-AC30*$Z$24 -> -5.2425 | AD40: =-AD30*$Z$24 -> -5.2425 | AF40: =-AF30*$AF$24 -> 0 | AG40: =-AG30*$AF$24 -> 0 | AH40: =-AH30*$AF$24 -> 0 | AI40: =-AI30*$AF$24 -> -5.848875 | AJ40: =-AJ30*$AF$24 -> -5.848875 | AL40: =-AL30*$AL$24 -> 0 | AM40: =-AM30*$AL$24 -> 0 | AN40: =-AN30*$AL$24 -> 0 | AO40: =-AO30*$AL$24 -> -5.2425 | AP40: =-AP30*$AL$24 -> -5.2425 | AR40: =-AR30*$AR$24 -> 0 | AS40: =-AS30*$AR$24 -> 0 | AT40: =-AT30*$AR$24 -> 0 | AU40: =-AU30*$AR$24 -> -5.2425 | AV40: =-AV30*$AR$24 -> -5.2425 | AX40: =-AX30*$AX$24 -> 0 | AY40: =-AY30*$AX$24 -> 0 | AZ40: =-AZ30*$AX$24 -> 0 | BA40: =-BA30*$AX$24 -> -5.2425 | BB40: =-BB30*$AX$24 -> -5.2425 | BD40: =-BD30*$BD$24 -> 0 | BE40: =-BE30*$BD$24 -> 0 | BF40: =-BF30*$BD$24 -> 0 | BG40: =-BG30*$BD$24 -> -5.2425 | BH40: =-BH30*$BD$24 -> -5.2425
A41: 3PL pick/pack + packaging (incl. hidden-fee uplift) | B41: 0 | C41: =-(Inputs!$G$88+Inputs!$G$90)*(1+Inputs!$G$92) -> -5.1 | D41: =-(Inputs!$G$88+Inputs!$G$89+Inputs!$G$90)*(1+Inputs!$G$92) -> -5.7 | E41: =-(Inputs!$G$88+Inputs!$G$91)*(1+Inputs!$G$92) -> -4.2 | F41: =-(Inputs!$G$88+Inputs!$G$91)*(1+Inputs!$G$92) -> -4.2 | H41: 0 | I41: =-(Inputs!$D$88+Inputs!$D$90)*(1+Inputs!$D$92) -> -6.4125 | J41: =-(Inputs!$D$88+Inputs!$D$89+Inputs!$D$90)*(1+Inputs!$D$92) -> -7.425 | K41: =-(Inputs!$D$88+Inputs!$D$91)*(1+Inputs!$D$92) -> -5.4 | L41: =-(Inputs!$D$88+Inputs!$D$91)*(1+Inputs!$D$92) -> -5.4 | N41: 0 | O41: =-(Inputs!$E$88+Inputs!$E$90)*(1+Inputs!$E$92) -> -5.1 | P41: =-(Inputs!$E$88+Inputs!$E$89+Inputs!$E$90)*(1+Inputs!$E$92) -> -5.7 | Q41: =-(Inputs!$E$88+Inputs!$E$91)*(1+Inputs!$E$92) -> -4.2 | R41: =-(Inputs!$E$88+Inputs!$E$91)*(1+Inputs!$E$92) -> -4.2 | T41: 0 | U41: =-(Inputs!$F$88+Inputs!$F$90)*(1+Inputs!$F$92) -> -3.3 | V41: =-(Inputs!$F$88+Inputs!$F$89+Inputs!$F$90)*(1+Inputs!$F$92) -> -3.74 | W41: =-(Inputs!$F$88+Inputs!$F$91)*(1+Inputs!$F$92) -> -2.585 | X41: =-(Inputs!$F$88+Inputs!$F$91)*(1+Inputs!$F$92) -> -2.585 | Z41: 0 | AA41: =-(Inputs!$E$88+Inputs!$E$90)*(1+Inputs!$E$92) -> -5.1 | AB41: =-(Inputs!$E$88+Inputs!$E$89+Inputs!$E$90)*(1+Inputs!$E$92) -> -5.7 | AC41: =-(Inputs!$E$88+Inputs!$E$91)*(1+Inputs!$E$92) -> -4.2 | AD41: =-(Inputs!$E$88+Inputs!$E$91)*(1+Inputs!$E$92) -> -4.2 | AF41: 0 | AG41: =-(Inputs!$E$88+Inputs!$E$90)*(1+Inputs!$E$92) -> -5.1 | AH41: =-(Inputs!$E$88+Inputs!$E$89+Inputs!$E$90)*(1+Inputs!$E$92) -> -5.7 | AI41: =-(Inputs!$E$88+Inputs!$E$91)*(1+Inputs!$E$92) -> -4.2 | AJ41: =-(Inputs!$E$88+Inputs!$E$91)*(1+Inputs!$E$92) -> -4.2 | AL41: 0 | AM41: =-(Inputs!$E$88+Inputs!$E$90)*(1+Inputs!$E$92) -> -5.1 | AN41: =-(Inputs!$E$88+Inputs!$E$89+Inputs!$E$90)*(1+Inputs!$E$92) -> -5.7 | AO41: =-(Inputs!$E$88+Inputs!$E$91)*(1+Inputs!$E$92) -> -4.2 | AP41: =-(Inputs!$E$88+Inputs!$E$91)*(1+Inputs!$E$92) -> -4.2 | AR41: 0 | AS41: =-(Inputs!$E$88+Inputs!$E$90)*(1+Inputs!$E$92) -> -5.1 | AT41: =-(Inputs!$E$88+Inputs!$E$89+Inputs!$E$90)*(1+Inputs!$E$92) -> -5.7 | AU41: =-(Inputs!$E$88+Inputs!$E$91)*(1+Inputs!$E$92) -> -4.2 | AV41: =-(Inputs!$E$88+Inputs!$E$91)*(1+Inputs!$E$92) -> -4.2 | AX41: 0 | AY41: =-(Inputs!$E$88+Inputs!$E$90)*(1+Inputs!$E$92) -> -5.1 | AZ41: =-(Inputs!$E$88+Inputs!$E$89+Inputs!$E$90)*(1+Inputs!$E$92) -> -5.7 | BA41: =-(Inputs!$E$88+Inputs!$E$91)*(1+Inputs!$E$92) -> -4.2 | BB41: =-(Inputs!$E$88+Inputs!$E$91)*(1+Inputs!$E$92) -> -4.2 | BD41: 0 | BE41: =-(Inputs!$E$88+Inputs!$E$90)*(1+Inputs!$E$92) -> -5.1 | BF41: =-(Inputs!$E$88+Inputs!$E$89+Inputs!$E$90)*(1+Inputs!$E$92) -> -5.7 | BG41: =-(Inputs!$E$88+Inputs!$E$91)*(1+Inputs!$E$92) -> -4.2 | BH41: =-(Inputs!$E$88+Inputs!$E$91)*(1+Inputs!$E$92) -> -4.2
A42: Postage (USPS Ground Advantage) | B42: 0 | C42: =-Inputs!$G$83*$B$9 -> -10.5 | D42: =-Inputs!$G$84*$B$9 -> -12.12 | E42: =-Inputs!$G$85*$B$9 -> -8.24 | F42: =-Inputs!$G$85*$B$9 -> -8.24 | H42: 0 | I42: =-Inputs!$D$83*$H$9 -> -11.96 | J42: =-Inputs!$D$84*$H$9 -> -14.21 | K42: =-Inputs!$D$85*$H$9 -> -8.595 | L42: =-Inputs!$D$85*$H$9 -> -8.595 | N42: 0 | O42: =-Inputs!$E$83*$N$9 -> -10.5 | P42: =-Inputs!$E$84*$N$9 -> -12.12 | Q42: =-Inputs!$E$85*$N$9 -> -8.24 | R42: =-Inputs!$E$85*$N$9 -> -8.24 | T42: 0 | U42: =-Inputs!$F$83*$T$9 -> -9.7222222 | V42: =-Inputs!$F$84*$T$9 -> -11.222222 | W42: =-Inputs!$F$85*$T$9 -> -6.4851852 | X42: =-Inputs!$F$85*$T$9 -> -6.4851852 | Z42: 0 | AA42: =-Inputs!$E$83*$Z$9 -> -10.5 | AB42: =-Inputs!$E$84*$Z$9 -> -12.12 | AC42: =-Inputs!$E$85*$Z$9 -> -8.24 | AD42: =-Inputs!$E$85*$Z$9 -> -8.24 | AF42: 0 | AG42: =-Inputs!$E$83*$AF$9 -> -10.5 | AH42: =-Inputs!$E$84*$AF$9 -> -12.12 | AI42: =-Inputs!$E$85*$AF$9 -> -8.24 | AJ42: =-Inputs!$E$85*$AF$9 -> -8.24 | AL42: 0 | AM42: =-Inputs!$E$83*$AL$9 -> -12.6 | AN42: =-Inputs!$E$84*$AL$9 -> -14.544 | AO42: =-Inputs!$E$85*$AL$9 -> -9.888 | AP42: =-Inputs!$E$85*$AL$9 -> -9.888 | AR42: 0 | AS42: =-Inputs!$E$83*$AR$9 -> -10.5 | AT42: =-Inputs!$E$84*$AR$9 -> -12.12 | AU42: =-Inputs!$E$85*$AR$9 -> -8.24 | AV42: =-Inputs!$E$85*$AR$9 -> -8.24 | AX42: 0 | AY42: =-Inputs!$E$83*$AX$9 -> -10.5 | AZ42: =-Inputs!$E$84*$AX$9 -> -12.12 | BA42: =-Inputs!$E$85*$AX$9 -> -8.24 | BB42: =-Inputs!$E$85*$AX$9 -> -8.24 | BD42: 0 | BE42: =-Inputs!$E$83*$BD$9 -> -10.5 | BF42: =-Inputs!$E$84*$BD$9 -> -12.12 | BG42: =-Inputs!$E$85*$BD$9 -> -8.24 | BH42: =-Inputs!$E$85*$BD$9 -> -8.24
A43: Payment processing | B43: =-(Inputs!$G$100*B35+Inputs!$G$101) -> -1.74971 | C43: =-(Inputs!$G$100*C35+Inputs!$G$101) -> -1.74971 | D43: =-(Inputs!$G$100*D35+Inputs!$G$101) -> -2.32942 | E43: =-(Inputs!$G$100*E35+Inputs!$G$101) -> -0.743439 | F43: =-(Inputs!$G$100*F35+Inputs!$G$101) -> -0.79271 | H43: =-(Inputs!$D$100*H35+Inputs!$D$101) -> -1.60471 | I43: =-(Inputs!$D$100*I35+Inputs!$D$101) -> -1.60471 | J43: =-(Inputs!$D$100*J35+Inputs!$D$101) -> -2.09742 | K43: =-(Inputs!$D$100*K35+Inputs!$D$101) -> -0.6695035 | L43: =-(Inputs!$D$100*L35+Inputs!$D$101) -> -0.73471 | N43: =-(Inputs!$E$100*N35+Inputs!$E$101) -> -1.74971 | O43: =-(Inputs!$E$100*O35+Inputs!$E$101) -> -1.74971 | P43: =-(Inputs!$E$100*P35+Inputs!$E$101) -> -2.32942 | Q43: =-(Inputs!$E$100*Q35+Inputs!$E$101) -> -0.743439 | R43: =-(Inputs!$E$100*R35+Inputs!$E$101) -> -0.79271 | T43: =-(Inputs!$F$100*T35+Inputs!$F$101) -> -2.03971 | U43: =-(Inputs!$F$100*U35+Inputs!$F$101) -> -2.03971 | V43: =-(Inputs!$F$100*V35+Inputs!$F$101) -> -2.70642 | W43: =-(Inputs!$F$100*W35+Inputs!$F$101) -> -0.756489 | X43: =-(Inputs!$F$100*X35+Inputs!$F$101) -> -0.92292 | Z43: =-(Inputs!$E$100*Z35+Inputs!$E$101) -> -1.74971 | AA43: =-(Inputs!$E$100*AA35+Inputs!$E$101) -> -1.74971 | AB43: =-(Inputs!$E$100*AB35+Inputs!$E$101) -> -2.32942 | AC43: =-(Inputs!$E$100*AC35+Inputs!$E$101) -> -0.743439 | AD43: =-(Inputs!$E$100*AD35+Inputs!$E$101) -> -0.79271 | AF43: =-(Inputs!$E$100*AF35+Inputs!$E$101) -> -1.74971 | AG43: =-(Inputs!$E$100*AG35+Inputs!$E$101) -> -1.74971 | AH43: =-(Inputs!$E$100*AH35+Inputs!$E$101) -> -2.32942 | AI43: =-(Inputs!$E$100*AI35+Inputs!$E$101) -> -0.743439 | AJ43: =-(Inputs!$E$100*AJ35+Inputs!$E$101) -> -0.79271 | AL43: =-(Inputs!$E$100*AL35+Inputs!$E$101) -> -1.74971 | AM43: =-(Inputs!$E$100*AM35+Inputs!$E$101) -> -1.74971 | AN43: =-(Inputs!$E$100*AN35+Inputs!$E$101) -> -2.32942 | AO43: =-(Inputs!$E$100*AO35+Inputs!$E$101) -> -0.743439 | AP43: =-(Inputs!$E$100*AP35+Inputs!$E$101) -> -0.79271 | AR43: =-(Inputs!$E$100*AR35+Inputs!$E$101) -> -1.74971 | AS43: =-(Inputs!$E$100*AS35+Inputs!$E$101) -> -1.74971 | AT43: =-(Inputs!$E$100*AT35+Inputs!$E$101) -> -2.32942 | AU43: =-(Inputs!$E$100*AU35+Inputs!$E$101) -> -0.743439 | AV43: =-(Inputs!$E$100*AV35+Inputs!$E$101) -> -0.79271 | AX43: =-(Inputs!$E$100*AX35+Inputs!$E$101) -> -1.74971 | AY43: =-(Inputs!$E$100*AY35+Inputs!$E$101) -> -1.74971 | AZ43: =-(Inputs!$E$100*AZ35+Inputs!$E$101) -> -2.32942 | BA43: =-(Inputs!$E$100*BA35+Inputs!$E$101) -> -0.743439 | BB43: =-(Inputs!$E$100*BB35+Inputs!$E$101) -> -0.79271 | BD43: =-(Inputs!$E$100*BD35+Inputs!$E$101) -> -1.74971 | BE43: =-(Inputs!$E$100*BE35+Inputs!$E$101) -> -1.74971 | BF43: =-(Inputs!$E$100*BF35+Inputs!$E$101) -> -2.32942 | BG43: =-(Inputs!$E$100*BG35+Inputs!$E$101) -> -0.743439 | BH43: =-(Inputs!$E$100*BH35+Inputs!$E$101) -> -0.79271
...

Sheet Cat_Cohort
A1: Cat_Cohort: 24-month cohort of 100 acquired customers (BASE CASE)
A2: LTV = contribution profit (never revenue). First-order profitability is reported separately so subscription renewals cannot hide an unprofitable first order. Segments: one-time only, occasional repeat buyers (one-time filter packs), filter subscribers (90-day).
A4: ="SELECTED SCENARIO COHORT: "&Inputs!$E$3&" | stage: "&Inputs!$E$4 -> SELECTED SCENARIO COHORT: Base | stage: Private label (OEM + 3PL, CPA months 4-12)
A6: Customers acquired (N) | B6: =Inputs!$G$9 -> 100
A7: Subscription attach (after any shock) | B7: =MIN(1,Inputs!$G$133*Cat_UnitEcon!$B$10) -> 0.2
A8: Non-subscriber 12-month repeat rate | B8: =Inputs!$G$139 -> 0.2
A9: Segment: subscribers | B9: =$B$6*$B$7 -> 20
A10: Segment: occasional repeat buyers | B10: =$B$6*(1-$B$7)*$B$8 -> 16
A11: Segment: one-time only | B11: =$B$6-$B$9-$B$10 -> 64
A12: First-order contribution before ads, per customer (mix) | B12: =Cat_UnitEcon!$B$57 -> 4.9991963
A13: Paid CAC per new customer | B13: =Cat_UnitEcon!$B$60 -> 45
A14: Contribution per subscription renewal order | B14: =Cat_UnitEcon!$E$50 -> -3.419322
A15: Contribution per occasional repeat order | B15: =Cat_UnitEcon!$F$50 -> -1.79168
A16: Churn before first renewal (incl. involuntary) | B16: =1-(1-MIN(1,Inputs!$G$135*Cat_UnitEcon!$B$11))*(1-MIN(1,Inputs!$G$137*Cat_UnitEcon!$B$11))^$B$18 -> 0.26564001
A17: Churn per later cycle (incl. involuntary) | B17: =1-(1-MIN(1,Inputs!$G$136*Cat_UnitEcon!$B$11))*(1-MIN(1,Inputs!$G$137*Cat_UnitEcon!$B$11))^$B$18 -> 0.16772534
A18: Renewal cadence (months) | B18: =Inputs!$G$134 -> 3
A19: Occasional: month of first repeat | B19: =Inputs!$G$140 -> 4
A20: Occasional: months between orders | B20: =Inputs!$G$141 -> 4
A21: Occasional: probability of each further order | B21: =Inputs!$G$142 -> 0.6
A22: First-order contribution - subscriber | B22: =Cat_UnitEcon!$B$63 -> 4.9991963
A23: First-order contribution - non-subscriber | B23: =Cat_UnitEcon!$B$64 -> 4.9991963
A24: First-order gross revenue (mix) - reference | B24: =Cat_UnitEcon!$B$59 -> 54.9875
A25: Renewal order gross revenue - reference | B25: =Cat_UnitEcon!$E$35 -> 15.291
A26: Occasional order gross revenue - reference | B26: =Cat_UnitEcon!$F$35 -> 16.99
A28: Month | B28: Total 1-24 | C28: 1 | D28: 2 | E28: 3 | F28: 4 | G28: 5 | H28: 6 | I28: 7 | J28: 8 | K28: 9 | L28: 10 | M28: 11 | N28: 12 | O28: 13 | P28: 14 | Q28: 15 | R28: 16 | S28: 17 | T28: 18 | U28: 19 | V28: 20 | W28: 21 | X28: 22 | Y28: 23 | Z28: 24
A29: Subscription renewal orders (paying subscribers) | B29: =SUM(C29:Z29) -> 63.345136 | C29: =IF(AND(C$28>1,MOD(C$28-1,$B$18)=0),$B$9*(1-$B$16)*(1-$B$17)^((C$28-1)/$B$18-1),0) -> 0 | D29: =IF(AND(D$28>1,MOD(D$28-1,$B$18)=0),$B$9*(1-$B$16)*(1-$B$17)^((D$28-1)/$B$18-1),0) -> 0 | E29: =IF(AND(E$28>1,MOD(E$28-1,$B$18)=0),$B$9*(1-$B$16)*(1-$B$17)^((E$28-1)/$B$18-1),0) -> 0 | F29: =IF(AND(F$28>1,MOD(F$28-1,$B$18)=0),$B$9*(1-$B$16)*(1-$B$17)^((F$28-1)/$B$18-1),0) -> 14.6872 | G29: =IF(AND(G$28>1,MOD(G$28-1,$B$18)=0),$B$9*(1-$B$16)*(1-$B$17)^((G$28-1)/$B$18-1),0) -> 0 | H29: =IF(AND(H$28>1,MOD(H$28-1,$B$18)=0),$B$9*(1-$B$16)*(1-$B$17)^((H$28-1)/$B$18-1),0) -> 0 | I29: =IF(AND(I$28>1,MOD(I$28-1,$B$18)=0),$B$9*(1-$B$16)*(1-$B$17)^((I$28-1)/$B$18-1),0) -> 12.223784 | J29: =IF(AND(J$28>1,MOD(J$28-1,$B$18)=0),$B$9*(1-$B$16)*(1-$B$17)^((J$28-1)/$B$18-1),0) -> 0 | ... Z29: =IF(AND(Z$28>1,MOD(Z$28-1,$B$18)=0),$B$9*(1-$B$16)*(1-$B$17)^((Z$28-1)/$B$18-1),0) -> 0
A30: Occasional repeat orders | B30: =SUM(C30:Z30) -> 38.13376 | C30: =IF(AND(C$28>=$B$19,MOD(C$28-$B$19,$B$20)=0),$B$10*$B$21^((C$28-$B$19)/$B$20),0) -> 0 | D30: =IF(AND(D$28>=$B$19,MOD(D$28-$B$19,$B$20)=0),$B$10*$B$21^((D$28-$B$19)/$B$20),0) -> 0 | E30: =IF(AND(E$28>=$B$19,MOD(E$28-$B$19,$B$20)=0),$B$10*$B$21^((E$28-$B$19)/$B$20),0) -> 0 | F30: =IF(AND(F$28>=$B$19,MOD(F$28-$B$19,$B$20)=0),$B$10*$B$21^((F$28-$B$19)/$B$20),0) -> 16 | G30: =IF(AND(G$28>=$B$19,MOD(G$28-$B$19,$B$20)=0),$B$10*$B$21^((G$28-$B$19)/$B$20),0) -> 0 | H30: =IF(AND(H$28>=$B$19,MOD(H$28-$B$19,$B$20)=0),$B$10*$B$21^((H$28-$B$19)/$B$20),0) -> 0 | I30: =IF(AND(I$28>=$B$19,MOD(I$28-$B$19,$B$20)=0),$B$10*$B$21^((I$28-$B$19)/$B$20),0) -> 0 | J30: =IF(AND(J$28>=$B$19,MOD(J$28-$B$19,$B$20)=0),$B$10*$B$21^((J$28-$B$19)/$B$20),0) -> 9.6 | ... Z30: =IF(AND(Z$28>=$B$19,MOD(Z$28-$B$19,$B$20)=0),$B$10*$B$21^((Z$28-$B$19)/$B$20),0) -> 1.24416
A31: Contribution - one-time-only segment | B31: =SUM(C31:Z31) -> 319.94856 | C31: =IF(C$28=1,$B$11*$B$23,0) -> 319.94856 | D31: =IF(D$28=1,$B$11*$B$23,0) -> 0 | E31: =IF(E$28=1,$B$11*$B$23,0) -> 0 | F31: =IF(F$28=1,$B$11*$B$23,0) -> 0 | G31: =IF(G$28=1,$B$11*$B$23,0) -> 0 | H31: =IF(H$28=1,$B$11*$B$23,0) -> 0 | I31: =IF(I$28=1,$B$11*$B$23,0) -> 0 | J31: =IF(J$28=1,$B$11*$B$23,0) -> 0 | ... Z31: =IF(Z$28=1,$B$11*$B$23,0) -> 0
A32: Contribution - occasional repeat segment | B32: =SUM(C32:Z32) -> 11.663646 | C32: =IF(C$28=1,$B$10*$B$23,0)+C30*$B$15 -> 79.987141 | D32: =IF(D$28=1,$B$10*$B$23,0)+D30*$B$15 -> 0 | E32: =IF(E$28=1,$B$10*$B$23,0)+E30*$B$15 -> 0 | F32: =IF(F$28=1,$B$10*$B$23,0)+F30*$B$15 -> -28.66688 | G32: =IF(G$28=1,$B$10*$B$23,0)+G30*$B$15 -> 0 | H32: =IF(H$28=1,$B$10*$B$23,0)+H30*$B$15 -> 0 | I32: =IF(I$28=1,$B$10*$B$23,0)+I30*$B$15 -> 0 | J32: =IF(J$28=1,$B$10*$B$23,0)+J30*$B$15 -> -17.200128 | ... Z32: =IF(Z$28=1,$B$10*$B$23,0)+Z30*$B$15 -> -2.2291366
A33: Contribution - subscriber segment | B33: =SUM(C33:Z33) -> -116.61349 | C33: =IF(C$28=1,$B$9*$B$22,0)+C29*$B$14 -> 99.983927 | D33: =IF(D$28=1,$B$9*$B$22,0)+D29*$B$14 -> 0 | E33: =IF(E$28=1,$B$9*$B$22,0)+E29*$B$14 -> 0 | F33: =IF(F$28=1,$B$9*$B$22,0)+F29*$B$14 -> -50.220266 | G33: =IF(G$28=1,$B$9*$B$22,0)+G29*$B$14 -> 0 | H33: =IF(H$28=1,$B$9*$B$22,0)+H29*$B$14 -> 0 | I33: =IF(I$28=1,$B$9*$B$22,0)+I29*$B$14 -> -41.797054 | J33: =IF(J$28=1,$B$9*$B$22,0)+J29*$B$14 -> 0 | ... Z33: =IF(Z$28=1,$B$9*$B$22,0)+Z29*$B$14 -> 0
A34: Total contribution before CAC | B34: =SUM(C34:Z34) -> 214.99872 | C34: =SUM(C31:C33) -> 499.91963 | D34: =SUM(D31:D33) -> 0 | E34: =SUM(E31:E33) -> 0 | F34: =SUM(F31:F33) -> -78.887146 | G34: =SUM(G31:G33) -> 0 | H34: =SUM(H31:H33) -> 0 | I34: =SUM(I31:I33) -> -41.797054 | J34: =SUM(J31:J33) -> -17.200128 | ... Z34: =SUM(Z31:Z33) -> -2.2291366
A35: CAC (paid, month 1) | B35: =SUM(C35:Z35) -> -4500 | C35: =IF(C$28=1,-$B$6*$B$13,0) -> -4500 | D35: =IF(D$28=1,-$B$6*$B$13,0) -> 0 | E35: =IF(E$28=1,-$B$6*$B$13,0) -> 0 | F35: =IF(F$28=1,-$B$6*$B$13,0) -> 0 | G35: =IF(G$28=1,-$B$6*$B$13,0) -> 0 | H35: =IF(H$28=1,-$B$6*$B$13,0) -> 0 | I35: =IF(I$28=1,-$B$6*$B$13,0) -> 0 | J35: =IF(J$28=1,-$B$6*$B$13,0) -> 0 | ... Z35: =IF(Z$28=1,-$B$6*$B$13,0) -> 0
A36: Net contribution after CAC | B36: =SUM(C36:Z36) -> -4285.0013 | C36: =C34+C35 -> -4000.0804 | D36: =D34+D35 -> 0 | E36: =E34+E35 -> 0 | F36: =F34+F35 -> -78.887146 | G36: =G34+G35 -> 0 | H36: =H34+H35 -> 0 | I36: =I34+I35 -> -41.797054 | J36: =J34+J35 -> -17.200128 | ... Z36: =Z34+Z35 -> -2.2291366
